<!-- <mujoco model="manipulation_generic">
   <include file="../../misc/skybox.xml" />
   <include file="../../misc/visual.xml" />
   <include file="../../misc/materials.xml" />
   <compiler angle="degree" coordinate="global" inertiafromgeom="true" />
   <default>
      <joint armature="0.01" damping=".1" limited="true" />
      <geom conaffinity="0" condim="3" contype="1" density="1000" friction=".7 .1 .1" material="self" />
   </default>
   <option integrator="RK4" timestep="0.002" />
      <actuator>
         <motor ctrllimited="true" ctrlrange="-1.0 1.0" gear="100" joint="left1_joint" />
         <motor ctrllimited="true" ctrlrange="-1.0 1.0" gear="100" joint="right1_joint" />
      </actuator>
      <worldbody>
         <light cutoff="100" diffuse="1 1 1" dir="-1 -0 -1.5" directional="true" exponent="1" pos="0 0 1.3" specular=".1 .1 .1" />
         <geom conaffinity="1" condim="3" material="grid" name="floor" pos="0 0 0" size="40 40 40" type="plane" />
         <body name="torso" pos="0 0 1.6">
            <camera mode="trackcom" name="tilted" pos="2.7 3 1" xyaxes="1 -.9 0 0 0 -1" />
            <camera mode="trackcom" name="track" pos="0 3 1" xyaxes="1 0 0 0 0 -1" />
            <joint armature="0" axis="1 0 0" damping="0" limited="false" name="rootx" pos="0 0 0" stiffness="0" type="slide" />
            <joint armature="0" axis="0 0 1" damping="0" limited="false" name="rootz" pos="0 0 0" ref="1.25" stiffness="0" type="slide" />
            <joint armature="0" axis="1 1 1" damping="0" limited="false" name="rooty" pos="0 0 1.25" stiffness="0" type="hinge" />
            <geom friction="0.9" fromto="0 0 1.6 0 0 1.0" name="torso_geom" size="0.07" type="capsule" />
            <body name="left1" pos="0 0 1.0">
               <geom friction="0.9" fromto="0 0 1.0 0 0 0.52" name="left1_geom" size="0.05600000000000001" type="capsule" />
               <joint axis="0 -1 0" name="left1_joint" pos="0 0 1.0" range="-85 85" type="hinge" />
         </body>
         <body name="right1" pos="0 0 1.0">
            <geom friction="0.9" fromto="0 0 1.0 0 0 0.52" name="right1" size="0.05600000000000001" type="capsule" />
            <joint axis="0 -1 0" name="right1_joint" pos="0 0 1.0" range="-85 85" type="hinge" />
         </body>
         </body>
      </worldbody>
</mujoco> -->

<mujoco model="manipulation_generic">
    <include file="../../misc/skybox.xml" />
    <include file="../../misc/visual.xml" />
    <include file="../../misc/materials.xml" />
    <compiler angle="degree" coordinate="local" inertiafromgeom="true" />
    <default>
        <joint armature="0.01" damping=".1" limited="true" />
        <geom conaffinity="0" condim="3" contype="1" density="1000" friction=".7 .1 .1" material="self" />
    </default>
    <option integrator="RK4" timestep="0.002" collision="dynamic"/>
        <actuator>
            <motor ctrllimited="true" ctrlrange="-1.0 1.0" gear="100" joint="joint_0" />
            <motor ctrllimited="true" ctrlrange="-1.0 1.0" gear="100" joint="joint_1" />
            <motor ctrllimited="true" ctrlrange="-1.0 1.0" gear="100" joint="joint_2" />
            <!-- <motor ctrllimited="true" ctrlrange="-1.0 1.0" gear="100" joint="right1_joint" /> -->
        </actuator>
        <worldbody>
            <light cutoff="100" diffuse="1 1 1" dir="-1 -0 -1.5" directional="true" exponent="1" pos="0 0 1.3" specular=".1 .1 .1" />
            <geom conaffinity="1" condim="3" material="grid" name="floor" pos="0 0 0" size="40 40 40" type="plane"/>
            <camera mode="trackcom" name="tilted" pos="2.7 3 1" xyaxes="1 -.9 0 0 0 -1" />
            <camera mode="trackcom" name="track" pos="0 3 1" xyaxes="1 0 0 0 0 -1" />


            <body name="table" pos="0 0 0">
                <geom conaffinity="1" friction="0.5" pos="0 0 0.25" name="table_geom" size="2 2 0.25" type="box" mass="100" rgba="0.2 0.2 0.2 1" />
                <body name="link_0" pos="0 0 0.5">
                    <geom friction="0.9" name="link_0_geom" size="0.05 0.05" pos="0 0 0.05" type="capsule"/>
                    <joint axis="0 0 1" name="joint_0" pos="0 0 0" range="-180 180" type="hinge" />
                    <body name="link_1" pos="0 0 0.1">
                        <geom friction="0.9" name="link_1_geom" size="0.05 0.3" pos="0 0 0.3" type="capsule"/>
                        <joint axis="0 1 0" name="joint_1" pos="0 0 0" range="-92 92" type="hinge" />
                        <body name="link_2" pos="0 0 0.6">
                            <geom friction="0.9" name="link_2_geom" size="0.05 0.3" pos="0 0 0.3" type="capsule" />
                            <joint axis="1 0 0" name="joint_2" pos="0 0 0" range="-180 180" type="hinge" />
                        </body>
                    </body>
                </body>

            </body>
            <body name="object" pos="0.4 -0.4 0.5501">
                <joint armature="0" damping="0" limited="false" name="object" pos="0 0 0" type="free" />
                <geom conaffinity="1" friction="0.8" pos="0 0 0" name="object_geom" size="0.05 0.05 0.05" type="box" mass="0.5"/>
            </body>

        </worldbody>
</mujoco>
